Workbook

Sheet Planilla
D1: (1) | E1: (2) | F1: (3) | G1: (4) | H1: (5) | K1: (6) | L1: (6)
A2: Fecha | B2: Salida del sol | C2: Puesta del sol | D2: Motivo de activacion | E2: Fenomeno Meteorologico | F2: Tipo de trabajo | G2: Vehiculo | H2: Equipo | I2: Urea Kilos | J2: Glicol Litros | K2: Prioridad de de Trabajo 1 | L2: Prioridad de de Trabajo 2 | M2: Superficie 1 | N2: Superficie 2 | O2: Superficies Total | P2: Superficie tratada quimicamente | Q2: Superficie Barrida | R2: Urea /sup | S2: Glicol/sup | T2: Temp. | U2: P. Rocio | V2: Humedad | W2: Presion | X2: Viento
A3: 45805 | B3: =IF(A3="","",VLOOKUP(Planilla!A3,#REF!,2,FALSE)) -> #REF! | C3: =IF(B3="","",VLOOKUP(Planilla!A3,#REF!,3,FALSE)) -> #REF! | D3: Preventivo | E3: Probabilidad de Nieve | F3: Esparcido | G3: Tractor Agco Allis | H3: Esparcidor Urea Cyra | I3: 1875 | K3: Pista, cabeceras, rodajes y plataforma | M3: =IF(K3="",0,VLOOKUP(K3,#REF!,2,FALSE)) -> #REF! | N3: =IF(L3="",0,VLOOKUP(L3,#REF!,2,FALSE)) -> 0 | O3: =M3+N3 -> #REF! | P3: =IF(F3="Barrido","",O3) -> #REF! | Q3: =IF(F3="Barrido",O3,"") | R3: =IF(I3<>"0",I3,"") -> 1875 | S3: =IF(J3<>"0",J3,"") -> 0 | T3: -1.6 | U3: -2.4 | V3: 95 | W3: 1018 | X3: 0
A4: 45805 | B4: =IF(A4="","",VLOOKUP(Planilla!A4,#REF!,2,FALSE)) -> #REF! | C4: =IF(B4="","",VLOOKUP(Planilla!A4,#REF!,3,FALSE)) -> #REF! | D4: Preventivo | E4: Nieve | F4: Esparcido | G4: Tractor Agco Allis | H4: Esparcidor Urea Cyra | I4: 2250 | K4: Pista, cabeceras y rodajes | L4: Parking, sendas peatonales | M4: =IF(K4="",0,VLOOKUP(K4,#REF!,2,FALSE)) -> #REF! | N4: =IF(L4="",0,VLOOKUP(L4,#REF!,2,FALSE)) -> #REF! | O4: =M4+N4 -> #REF! | P4: =IF(F4="Barrido","",O4) -> #REF! | Q4: =IF(F4="Barrido",O4,"") | R4: =IF(I4<>"0",I4,"") -> 2250 | S4: =IF(J4<>"0",J4,"") -> 0 | T4: -0.3 | U4: -1.5 | V4: 92 | W4: 1016 | X4: 0
A5: 45805 | D5: Preventivo | E5: Nieve | F5: Prueba de frenado | G5: Movil 1 AB743ZN | H5: Descelerometro | K5: Pista | T5: 0 | U5: -1.2 | V5: 92 | W5: 1016 | X5: 0.3
A6: 45805 | B6: =IF(A6="","",VLOOKUP(Planilla!A6,#REF!,2,FALSE)) -> #REF! | C6: =IF(B6="","",VLOOKUP(Planilla!A6,#REF!,3,FALSE)) -> #REF! | D6: Preventivo | E6: Probabilidad de Hielo | F6: Otros rociado | G6: Mochila | H6: Mochila Giber 12 Lts | J6: 20 | L6: Parking, sendas peatonales | M6: =IF(K6="",0,VLOOKUP(K6,#REF!,2,FALSE)) -> 0 | N6: =IF(L6="",0,VLOOKUP(L6,#REF!,2,FALSE)) -> #REF! | O6: =M6+N6 -> #REF! | P6: =IF(F6="Barrido","",O6) -> #REF! | Q6: =IF(F6="Barrido",O6,"") | R6: =IF(I6<>"0",I6,"") -> 0 | S6: =IF(J6<>"0",J6,"") -> 20 | T6: -1.7 | U6: -2.2 | V6: 95 | W6: 1017 | X6: 0
A7: 45805 | B7: =IF(A7="","",VLOOKUP(Planilla!A7,#REF!,2,FALSE)) -> #REF! | C7: =IF(B7="","",VLOOKUP(Planilla!A7,#REF!,3,FALSE)) -> #REF! | D7: Preventivo | E7: Nieve | F7: Barrido | G7: Tractor MF7615 2018 | H7: Barredora MB 3616 TRT 2018 | K7: Pista, cabeceras y rodajes | M7: =IF(K7="",0,VLOOKUP(K7,#REF!,2,FALSE)) -> #REF! | N7: =IF(L7="",0,VLOOKUP(L7,#REF!,2,FALSE)) -> 0 | O7: =M7+N7 -> #REF! | P7: =IF(F7="Barrido","",O7) | Q7: =IF(F7="Barrido",O7,"") -> #REF! | R7: =IF(I7<>"0",I7,"") -> 0 | S7: =IF(J7<>"0",J7,"") -> 0 | T7: -0.2 | U7: -1.4 | V7: 92 | W7: 1016 | X7: 1.4
A8: 45805 | B8: =IF(A8="","",VLOOKUP(Planilla!A8,#REF!,2,FALSE)) -> #REF! | C8: =IF(B8="","",VLOOKUP(Planilla!A8,#REF!,3,FALSE)) -> #REF! | D8: Preventivo | E8: Nieve | F8: Barrido | G8: Tractor MF7615 2018 | H8: Barredora MB 3616 TRT 2018 | K8: Plataforma | M8: =IF(K8="",0,VLOOKUP(K8,#REF!,2,FALSE)) -> #REF! | N8: =IF(L8="",0,VLOOKUP(L8,#REF!,2,FALSE)) -> 0 | O8: =M8+N8 -> #REF! | P8: =IF(F8="Barrido","",O8) | Q8: =IF(F8="Barrido",O8,"") -> #REF! | R8: =IF(I8<>"0",I8,"") -> 0 | S8: =IF(J8<>"0",J8,"") -> 0 | T8: 1 | U8: 0.8 | V8: 99 | W8: 1011 | X8: 1.2
A9: 45805 | B9: =IF(A9="","",VLOOKUP(Planilla!A9,#REF!,2,FALSE)) -> #REF! | C9: =IF(B9="","",VLOOKUP(Planilla!A9,#REF!,3,FALSE)) -> #REF! | D9: Preventivo | E9: Rocio helado | F9: Esparcido | G9: Tractor Agco Allis | H9: Esparcidor Urea Cyra | I9: 400 | K9: Plataforma | M9: =IF(K9="",0,VLOOKUP(K9,#REF!,2,FALSE)) -> #REF! | N9: =IF(L9="",0,VLOOKUP(L9,#REF!,2,FALSE)) -> 0 | O9: =M9+N9 -> #REF! | P9: =IF(F9="Barrido","",O9) -> #REF! | Q9: =IF(F9="Barrido",O9,"") | R9: =IF(I9<>"0",I9,"") -> 400 | S9: =IF(J9<>"0",J9,"") -> 0 | T9: 1 | U9: 0.8 | V9: 99 | W9: 1011 | X9: 1.2
A10: 45805 | B10: =IF(A10="","",VLOOKUP(Planilla!A10,#REF!,2,FALSE)) -> #REF! | C10: =IF(B10="","",VLOOKUP(Planilla!A10,#REF!,3,FALSE)) -> #REF! | D10: Preventivo | E10: Probabilidad de Hielo | F10: Rociado | G10: Tractor MF7615 2019 | H10: Rociador de Glicol Capurelli | J10: 700 | K10: Pista, cabeceras y rodajes | M10: =IF(K10="",0,VLOOKUP(K10,#REF!,2,FALSE)) -> #REF! | N10: =IF(L10="",0,VLOOKUP(L10,#REF!,2,FALSE)) -> 0 | O10: =M10+N10 -> #REF! | P10: =IF(F10="Barrido","",O10) -> #REF! | Q10: =IF(F10="Barrido",O10,"") | R10: =IF(I10<>"0",I10,"") -> 0 | S10: =IF(J10<>"0",J10,"") -> 700 | T10: 1.3 | U10: 1.2 | V10: 99 | W10: 1010 | X10: 2.4
A11: 45805 | B11: =IF(A11="","",VLOOKUP(Planilla!A11,#REF!,2,FALSE)) -> #REF! | C11: =IF(B11="","",VLOOKUP(Planilla!A11,#REF!,3,FALSE)) -> #REF! | D11: Preventivo | E11: Rocio helado | F11: Esparcido | G11: Tractor Agco Allis | H11: Esparcidor Urea Cyra | I11: 100 | K11: Parking, sendas peatonales | M11: =IF(K11="",0,VLOOKUP(K11,#REF!,2,FALSE)) -> #REF! | N11: =IF(L11="",0,VLOOKUP(L11,#REF!,2,FALSE)) -> 0 | O11: =M11+N11 -> #REF! | P11: =IF(F11="Barrido","",O11) -> #REF! | Q11: =IF(F11="Barrido",O11,"") | R11: =IF(I11<>"0",I11,"") -> 100 | S11: =IF(J11<>"0",J11,"") -> 0 | T11: 1.6 | U11: 1.4 | V11: 99 | W11: 1010 | X11: 4.9
A12: 45805 | D12: Preventivo | E12: Probabilidad de Hielo | F12: Prueba de frenado | G12: Movil 1 AB743ZN | H12: Descelerometro | K12: Pista | T12: -2.2 | U12: -2.3 | V12: 99 | W12: 1008 | X12: 0
A13: 45806 | B13: =IF(A13="","",VLOOKUP(Planilla!A13,#REF!,2,FALSE)) -> #REF! | C13: =IF(B13="","",VLOOKUP(Planilla!A13,#REF!,3,FALSE)) -> #REF! | D13: Correctivo | E13: Probabilidad de Hielo | F13: Rociado | G13: Tractor MF7615 2019 | H13: Rociador de Glicol Capurelli | J13: 500 | L13: Parking, sendas peatonales | M13: =IF(K13="",0,VLOOKUP(K13,#REF!,2,FALSE)) -> 0 | N13: =IF(L13="",0,VLOOKUP(L13,#REF!,2,FALSE)) -> #REF! | O13: =M13+N13 -> #REF! | P13: =IF(F13="Barrido","",O13) -> #REF! | Q13: =IF(F13="Barrido",O13,"") | R13: =IF(I13<>"0",I13,"") -> 0 | S13: =IF(J13<>"0",J13,"") -> 500 | T13: 0.9 | U13: 0.7 | V13: 99 | W13: 1008 | X13: 15.9
A14: 45806 | B14: =IF(A14="","",VLOOKUP(Planilla!A14,#REF!,2,FALSE)) -> #REF! | C14: =IF(B14="","",VLOOKUP(Planilla!A14,#REF!,3,FALSE)) -> #REF! | D14: Preventivo | E14: Probabilidad de Hielo | F14: Rociado | G14: Tractor MF7615 2019 | H14: Rociador de Glicol Capurelli | J14: 1300 | K14: Pista, cabeceras y rodajes | M14: =IF(K14="",0,VLOOKUP(K14,#REF!,2,FALSE)) -> #REF! | N14: =IF(L14="",0,VLOOKUP(L14,#REF!,2,FALSE)) -> 0 | O14: =M14+N14 -> #REF! | P14: =IF(F14="Barrido","",O14) -> #REF! | Q14: =IF(F14="Barrido",O14,"") | R14: =IF(I14<>"0",I14,"") -> 0 | S14: =IF(J14<>"0",J14,"") -> 1300 | T14: 1.5 | U14: 1.2 | V14: 98 | W14: 1009 | X14: 18.9
A15: 45806 | B15: =IF(A15="","",VLOOKUP(Planilla!A15,#REF!,2,FALSE)) -> #REF! | C15: =IF(B15="","",VLOOKUP(Planilla!A15,#REF!,3,FALSE)) -> #REF! | D15: Preventivo | E15: Probabilidad de Hielo | F15: Prueba de frenado | G15: Movil 1 AB743ZN | H15: Descelerometro | K15: Pista | M15: =IF(K15="",0,VLOOKUP(K15,#REF!,2,FALSE)) -> #REF! | N15: =IF(L15="",0,VLOOKUP(L15,#REF!,2,FALSE)) -> 0 | O15: =M15+N15 -> #REF! | P15: =IF(F15="Barrido","",O15) -> #REF! | Q15: =IF(F15="Barrido",O15,"") | R15: =IF(I15<>"0",I15,"") -> 0 | S15: =IF(J15<>"0",J15,"") -> 0 | T15: 2.2 | U15: 1.8 | V15: 98 | W15: 1009 | X15: 4.6
A16: 45807 | B16: =IF(A16="","",VLOOKUP(Planilla!A16,#REF!,2,FALSE)) -> #REF! | C16: =IF(B16="","",VLOOKUP(Planilla!A16,#REF!,3,FALSE)) -> #REF! | D16: Preventivo | E16: Probabilidad de Hielo | F16: Prueba de frenado | G16: Movil 1 AB743ZN | H16: Descelerometro | K16: Pista | M16: =IF(K16="",0,VLOOKUP(K16,#REF!,2,FALSE)) -> #REF! | N16: =IF(L16="",0,VLOOKUP(L16,#REF!,2,FALSE)) -> 0 | O16: =M16+N16 -> #REF! | P16: =IF(F16="Barrido","",O16) -> #REF! | Q16: =IF(F16="Barrido",O16,"") | R16: =IF(I16<>"0",I16,"") -> 0 | S16: =IF(J16<>"0",J16,"") -> 0 | T16: 5.9 | U16: 5.6 | V16: 98 | W16: 1002 | X16: 6.9
A17: 45808 | B17: =IF(A17="","",VLOOKUP(Planilla!A17,#REF!,2,FALSE)) -> #REF! | C17: =IF(B17="","",VLOOKUP(Planilla!A17,#REF!,3,FALSE)) -> #REF! | D17: Preventivo | E17: Probabilidad de Hielo | F17: Barrido | G17: Tractor MF7615 2018 | H17: Barredora MB 3616 TRT 2018 | K17: Plataforma | M17: =IF(K17="",0,VLOOKUP(K17,#REF!,2,FALSE)) -> #REF! | N17: =IF(L17="",0,VLOOKUP(L17,#REF!,2,FALSE)) -> 0 | O17: =M17+N17 -> #REF! | P17: =IF(F17="Barrido","",O17) | Q17: =IF(F17="Barrido",O17,"") -> #REF! | R17: =IF(I17<>"0",I17,"") -> 0 | S17: =IF(J17<>"0",J17,"") -> 0 | T17: 2.6 | U17: 2.4 | V17: 99 | W17: 1011 | X17: 8.4
A18: 45808 | B18: =IF(A18="","",VLOOKUP(Planilla!A18,#REF!,2,FALSE)) -> #REF! | C18: =IF(B18="","",VLOOKUP(Planilla!A18,#REF!,3,FALSE)) -> #REF! | D18: Preventivo | E18: Probabilidad de Hielo | F18: Esparcido | G18: Tractor Agco Allis | H18: Esparcidor Urea Cyra | I18: 250 | K18: Plataforma | M18: =IF(K18="",0,VLOOKUP(K18,#REF!,2,FALSE)) -> #REF! | N18: =IF(L18="",0,VLOOKUP(L18,#REF!,2,FALSE)) -> 0 | O18: =M18+N18 -> #REF! | P18: =IF(F18="Barrido","",O18) -> #REF! | Q18: =IF(F18="Barrido",O18,"") | R18: =IF(I18<>"0",I18,"") -> 250 | S18: =IF(J18<>"0",J18,"") -> 0 | T18: 2.3 | U18: 1.9 | V18: 97 | W18: 1011 | X18: 10.3
A19: 45809 | B19: =IF(A19="","",VLOOKUP(Planilla!A19,#REF!,2,FALSE)) -> #REF! | C19: =IF(B19="","",VLOOKUP(Planilla!A19,#REF!,3,FALSE)) -> #REF! | D19: Preventivo | E19: Probabilidad de Hielo | F19: Barrido | G19: Tractor MF7615 2018 | H19: Barredora MB 3616 TRT 2018 | K19: Plataforma | M19: =IF(K19="",0,VLOOKUP(K19,#REF!,2,FALSE)) -> #REF! | N19: =IF(L19="",0,VLOOKUP(L19,#REF!,2,FALSE)) -> 0 | O19: =M19+N19 -> #REF! | P19: =IF(F19="Barrido","",O19) | Q19: =IF(F19="Barrido",O19,"") -> #REF! | R19: =IF(I19<>"0",I19,"") -> 0 | S19: =IF(J19<>"0",J19,"") -> 0 | T19: 2.6 | U19: 2.3 | V19: 98 | W19: 995 | X19: 8.7
A20: 45809 | B20: =IF(A20="","",VLOOKUP(Planilla!A20,#REF!,2,FALSE)) -> #REF! | C20: =IF(B20="","",VLOOKUP(Planilla!A20,#REF!,3,FALSE)) -> #REF! | D20: Preventivo | E20: Probabilidad de Hielo | F20: Esparcido | G20: Tractor Agco Allis | H20: Esparcidor Urea Cyra | I20: 375 | K20: Plataforma | M20: =IF(K20="",0,VLOOKUP(K20,#REF!,2,FALSE)) -> #REF! | N20: =IF(L20="",0,VLOOKUP(L20,#REF!,2,FALSE)) -> 0 | O20: =M20+N20 -> #REF! | P20: =IF(F20="Barrido","",O20) -> #REF! | Q20: =IF(F20="Barrido",O20,"") | R20: =IF(I20<>"0",I20,"") -> 375 | S20: =IF(J20<>"0",J20,"") -> 0 | T20: 2.1 | U20: 1.8 | V20: 98 | W20: 994 | X20: 6.4
A21: 45809 | B21: =IF(A21="","",VLOOKUP(Planilla!A21,#REF!,2,FALSE)) -> #REF! | C21: =IF(B21="","",VLOOKUP(Planilla!A21,#REF!,3,FALSE)) -> #REF! | D21: Preventivo | E21: Probabilidad de Hielo | F21: Otros esparcido | G21: Manual | H21: Herramientas manuales | I21: 25 | L21: Parking | M21: =IF(K21="",0,VLOOKUP(K21,#REF!,2,FALSE)) -> 0 | N21: =IF(L21="",0,VLOOKUP(L21,#REF!,2,FALSE)) -> #REF! | O21: =M21+N21 -> #REF! | P21: =IF(F21="Barrido","",O21) -> #REF! | Q21: =IF(F21="Barrido",O21,"") | R21: =IF(I21<>"0",I21,"") -> 25 | S21: =IF(J21<>"0",J21,"") -> 0 | T21: 2.3 | U21: 1.9 | V21: 97 | W21: 994 | X21: 14
A22: 45810 | B22: =IF(A22="","",VLOOKUP(Planilla!A22,#REF!,2,FALSE)) -> #REF! | C22: =IF(B22="","",VLOOKUP(Planilla!A22,#REF!,3,FALSE)) -> #REF! | D22: Preventivo | E22: Rocio helado | F22: Rociado | G22: Tractor MF7615 2019 | H22: Rociador de Glicol Capurelli | J22: 1000 | K22: Pista, cabeceras y rodajes | M22: =IF(K22="",0,VLOOKUP(K22,#REF!,2,FALSE)) -> #REF! | N22: =IF(L22="",0,VLOOKUP(L22,#REF!,2,FALSE)) -> 0 | O22: =M22+N22 -> #REF! | P22: =IF(F22="Barrido","",O22) -> #REF! | Q22: =IF(F22="Barrido",O22,"") | R22: =IF(I22<>"0",I22,"") -> 0 | S22: =IF(J22<>"0",J22,"") -> 1000 | T22: -1.4 | U22: -1.6 | V22: 96 | W22: 1000 | X22: 6.3
A23: 45811 | B23: =IF(A23="","",VLOOKUP(Planilla!A23,#REF!,2,FALSE)) -> #REF! | C23: =IF(B23="","",VLOOKUP(Planilla!A23,#REF!,3,FALSE)) -> #REF! | D23: Preventivo | E23: Probabilidad de Hielo | F23: Barrido | G23: Tractor MF7615 2018 | H23: Barredora MB 3616 TRT 2018 | K23: Plataforma | M23: =IF(K23="",0,VLOOKUP(K23,#REF!,2,FALSE)) -> #REF! | N23: =IF(L23="",0,VLOOKUP(L23,#REF!,2,FALSE)) -> 0 | O23: =M23+N23 -> #REF! | P23: =IF(F23="Barrido","",O23) | Q23: =IF(F23="Barrido",O23,"") -> #REF! | R23: =IF(I23<>"0",I23,"") -> 0 | S23: =IF(J23<>"0",J23,"") -> 0 | T23: 2.2 | U23: 0.8 | V23: 90 | W23: 1003 | X23: 3.8
A24: 45813 | B24: =IF(A24="","",VLOOKUP(Planilla!A24,#REF!,2,FALSE)) -> #REF! | C24: =IF(B24="","",VLOOKUP(Planilla!A24,#REF!,3,FALSE)) -> #REF! | D24: Preventivo | E24: Probabilidad de Hielo | F24: Barrido | G24: Tractor MF7615 2018 | H24: Barredora MB 3616 TRT 2018 | K24: Plataforma | M24: =IF(K24="",0,VLOOKUP(K24,#REF!,2,FALSE)) -> #REF! | N24: =IF(L24="",0,VLOOKUP(L24,#REF!,2,FALSE)) -> 0 | O24: =M24+N24 -> #REF! | P24: =IF(F24="Barrido","",O24) | Q24: =IF(F24="Barrido",O24,"") -> #REF! | R24: =IF(I24<>"0",I24,"") -> 0 | S24: =IF(J24<>"0",J24,"") -> 0 | T24: 0.4 | U24: 0 | V24: 91 | W24: 1005.2 | X24: 10
A25: 45814 | B25: =IF(A25="","",VLOOKUP(Planilla!A25,#REF!,2,FALSE)) -> #REF! | C25: =IF(B25="","",VLOOKUP(Planilla!A25,#REF!,3,FALSE)) -> #REF! | D25: Preventivo | E25: Escarcha Frost | F25: Rociado | G25: Tractor MF7615 2019 | H25: Rociador de Glicol Capurelli | J25: 1800 | K25: Pista, cabeceras, rodajes y plataforma | M25: =IF(K25="",0,VLOOKUP(K25,#REF!,2,FALSE)) -> #REF! | N25: =IF(L25="",0,VLOOKUP(L25,#REF!,2,FALSE)) -> 0 | O25: =M25+N25 -> #REF! | P25: =IF(F25="Barrido","",O25) -> #REF! | Q25: =IF(F25="Barrido",O25,"") | R25: =IF(I25<>"0",I25,"") -> 0 | S25: =IF(J25<>"0",J25,"") -> 1800 | T25: 0 | U25: -1 | V25: 93 | W25: 1010.2 | X25: 1.8
A26: 45814 | B26: =IF(A26="","",VLOOKUP(Planilla!A26,#REF!,2,FALSE)) -> #REF! | C26: =IF(B26="","",VLOOKUP(Planilla!A26,#REF!,3,FALSE)) -> #REF! | D26: Preventivo | E26: Escarcha Frost | F26: Rociado | G26: Tractor MF7615 2019 | H26: Rociador de Glicol Capurelli | J26: 600 | K26: Parking | L26: Otros | M26: =IF(K26="",0,VLOOKUP(K26,#REF!,2,FALSE)) -> #REF! | N26: =IF(L26="",0,VLOOKUP(L26,#REF!,2,FALSE)) -> #REF! | O26: =M26+N26 -> #REF! | P26: =IF(F26="Barrido","",O26) -> #REF! | Q26: =IF(F26="Barrido",O26,"") | R26: =IF(I26<>"0",I26,"") -> 0 | S26: =IF(J26<>"0",J26,"") -> 600 | T26: 0.9 | U26: -1 | V26: 89 | W26: 1005.7 | X26: 10
A27: 45815 | B27: =IF(A27="","",VLOOKUP(Planilla!A27,#REF!,2,FALSE)) -> #REF! | C27: =IF(B27="","",VLOOKUP(Planilla!A27,#REF!,3,FALSE)) -> #REF! | D27: Preventivo | E27: Probabilidad de Hielo | F27: Prueba de frenado | G27: Movil 1 AB743ZN | H27: Descelerometro | K27: Pista | M27: =IF(K27="",0,VLOOKUP(K27,#REF!,2,FALSE)) -> #REF! | N27: =IF(L27="",0,VLOOKUP(L27,#REF!,2,FALSE)) -> 0 | O27: =M27+N27 -> #REF! | P27: =IF(F27="Barrido","",O27) -> #REF! | Q27: =IF(F27="Barrido",O27,"") | R27: =IF(I27<>"0",I27,"") -> 0 | S27: =IF(J27<>"0",J27,"") -> 0 | T27: -2 | U27: -4 | V27: 99 | W27: 1020 | X27: 6.1
A28: 45815 | B28: =IF(A28="","",VLOOKUP(Planilla!A28,#REF!,2,FALSE)) -> #REF! | C28: =IF(B28="","",VLOOKUP(Planilla!A28,#REF!,3,FALSE)) -> #REF! | D28: Preventivo | E28: Probabilidad de Hielo | F28: Rociado | G28: Tractor MF7615 2019 | H28: Rociador de Glicol Capurelli | J28: 1100 | K28: Pista y cabeceras | L28: Plataforma | M28: =IF(K28="",0,VLOOKUP(K28,#REF!,2,FALSE)) -> #REF! | N28: =IF(L28="",0,VLOOKUP(L28,#REF!,2,FALSE)) -> #REF! | O28: =M28+N28 -> #REF! | P28: =IF(F28="Barrido","",O28) -> #REF! | Q28: =IF(F28="Barrido",O28,"") | R28: =IF(I28<>"0",I28,"") -> 0 | S28: =IF(J28<>"0",J28,"") -> 1100 | T28: -1 | U28: -1 | V28: 100 | W28: 1017 | X28: 10
A29: 45820 | B29: =IF(A29="","",VLOOKUP(Planilla!A29,#REF!,2,FALSE)) -> #REF! | C29: =IF(B29="","",VLOOKUP(Planilla!A29,#REF!,3,FALSE)) -> #REF! | D29: Preventivo | E29: Probabilidad de Hielo | F29: Barrido | G29: Tractor MF7615 2018 | H29: Barredora MB 3616 TRT 2018 | K29: Plataforma | M29: =IF(K29="",0,VLOOKUP(K29,#REF!,2,FALSE)) -> #REF! | N29: =IF(L29="",0,VLOOKUP(L29,#REF!,2,FALSE)) -> 0 | O29: =M29+N29 -> #REF! | P29: =IF(F29="Barrido","",O29) | Q29: =IF(F29="Barrido",O29,"") -> #REF! | R29: =IF(I29<>"0",I29,"") -> 0 | S29: =IF(J29<>"0",J29,"") -> 0 | T29: 4 | U29: 3 | V29: 99 | W29: 1002 | X29: 2.9
A30: 45823 | B30: =IF(A30="","",VLOOKUP(Planilla!A30,#REF!,2,FALSE)) -> #REF! | C30: =IF(B30="","",VLOOKUP(Planilla!A30,#REF!,3,FALSE)) -> #REF! | D30: Preventivo | E30: Rocio helado | F30: Prueba de frenado | G30: Movil 1 AB743ZN | H30: Descelerometro | K30: Pista | M30: =IF(K30="",0,VLOOKUP(K30,#REF!,2,FALSE)) -> #REF! | N30: =IF(L30="",0,VLOOKUP(L30,#REF!,2,FALSE)) -> 0 | O30: =M30+N30 -> #REF! | P30: =IF(F30="Barrido","",O30) -> #REF! | Q30: =IF(F30="Barrido",O30,"") | R30: =IF(I30<>"0",I30,"") -> 0 | S30: =IF(J30<>"0",J30,"") -> 0 | T30: -0.6 | U30: -0.8 | V30: 99 | W30: 1005 | X30: 3.6
A31: 45823 | B31: =IF(A31="","",VLOOKUP(Planilla!A31,#REF!,2,FALSE)) -> #REF! | C31: =IF(B31="","",VLOOKUP(Planilla!A31,#REF!,3,FALSE)) -> #REF! | D31: Preventivo | E31: Rocio helado | F31: Prueba de frenado | G31: Movil 1 AB743ZN | H31: Descelerometro | K31: Pista | M31: =IF(K31="",0,VLOOKUP(K31,#REF!,2,FALSE)) -> #REF! | N31: =IF(L31="",0,VLOOKUP(L31,#REF!,2,FALSE)) -> 0 | O31: =M31+N31 -> #REF! | P31: =IF(F31="Barrido","",O31) -> #REF! | Q31: =IF(F31="Barrido",O31,"") | R31: =IF(I31<>"0",I31,"") -> 0 | S31: =IF(J31<>"0",J31,"") -> 0 | T31: -1.3 | U31: -1.5 | V31: 99 | W31: 1005 | X31: 4.2
A32: 45823 | B32: =IF(A32="","",VLOOKUP(Planilla!A32,#REF!,2,FALSE)) -> #REF! | C32: =IF(B32="","",VLOOKUP(Planilla!A32,#REF!,3,FALSE)) -> #REF! | D32: Preventivo | E32: Rocio helado | F32: Prueba de frenado | G32: Movil 1 AB743ZN | H32: Descelerometro | K32: Pista | M32: =IF(K32="",0,VLOOKUP(K32,#REF!,2,FALSE)) -> #REF! | N32: =IF(L32="",0,VLOOKUP(L32,#REF!,2,FALSE)) -> 0 | O32: =M32+N32 -> #REF! | P32: =IF(F32="Barrido","",O32) -> #REF! | Q32: =IF(F32="Barrido",O32,"") | R32: =IF(I32<>"0",I32,"") -> 0 | S32: =IF(J32<>"0",J32,"") -> 0 | T32: -2.7 | U32: -2.9 | V32: 99 | W32: 1004 | X32: 7.5
A33: 45824 | B33: =IF(A33="","",VLOOKUP(Planilla!A33,#REF!,2,FALSE)) -> #REF! | C33: =IF(B33="","",VLOOKUP(Planilla!A33,#REF!,3,FALSE)) -> #REF! | D33: Preventivo | E33: Rocio helado | F33: Prueba de frenado | G33: Movil 1 AB743ZN | H33: Descelerometro | K33: Pista | M33: =IF(K33="",0,VLOOKUP(K33,#REF!,2,FALSE)) -> #REF! | N33: =IF(L33="",0,VLOOKUP(L33,#REF!,2,FALSE)) -> 0 | O33: =M33+N33 -> #REF! | P33: =IF(F33="Barrido","",O33) -> #REF! | Q33: =IF(F33="Barrido",O33,"") | R33: =IF(I33<>"0",I33,"") -> 0 | S33: =IF(J33<>"0",J33,"") -> 0 | T33: -3.2 | U33: -3.3 | V33: 99 | W33: 1004 | X33: 4.8
A34: 45823 | B34: =IF(A34="","",VLOOKUP(Planilla!A34,#REF!,2,FALSE)) -> #REF! | C34: =IF(B34="","",VLOOKUP(Planilla!A34,#REF!,3,FALSE)) -> #REF! | D34: Preventivo | E34: Rocio helado | F34: Rociado | G34: Tractor MF7615 2019 | H34: Rociador de Glicol Capurelli | J34: 2750 | K34: Pista, cabeceras, rodajes y plataforma | M34: =IF(K34="",0,VLOOKUP(K34,#REF!,2,FALSE)) -> #REF! | N34: =IF(L34="",0,VLOOKUP(L34,#REF!,2,FALSE)) -> 0 | O34: =M34+N34 -> #REF! | P34: =IF(F34="Barrido","",O34) -> #REF! | Q34: =IF(F34="Barrido",O34,"") | R34: =IF(I34<>"0",I34,"") -> 0 | S34: =IF(J34<>"0",J34,"") -> 2750 | T34: -3 | U34: -3.2 | V34: 99 | W34: 1005 | X34: 4.5
A35: 45824 | B35: =IF(A35="","",VLOOKUP(Planilla!A35,#REF!,2,FALSE)) -> #REF! | C35: =IF(B35="","",VLOOKUP(Planilla!A35,#REF!,3,FALSE)) -> #REF! | D35: Preventivo | E35: Rocio helado | F35: Rociado | G35: Tractor MF7615 2019 | H35: Rociador de Glicol Capurelli | J35: 850 | K35: Cabeceras, plataforma | L35: Parking | M35: =IF(K35="",0,VLOOKUP(K35,#REF!,2,FALSE)) -> #REF! | N35: =IF(L35="",0,VLOOKUP(L35,#REF!,2,FALSE)) -> #REF! | O35: =M35+N35 -> #REF! | P35: =IF(F35="Barrido","",O35) -> #REF! | Q35: =IF(F35="Barrido",O35,"") | R35: =IF(I35<>"0",I35,"") -> 0 | S35: =IF(J35<>"0",J35,"") -> 850 | T35: -3.7 | U35: -3.9 | V35: 99 | W35: 1004 | X35: 0.4
A36: 45824 | B36: =IF(A36="","",VLOOKUP(Planilla!A36,#REF!,2,FALSE)) -> #REF! | C36: =IF(B36="","",VLOOKUP(Planilla!A36,#REF!,3,FALSE)) -> #REF! | D36: Preventivo | E36: Rocio helado | F36: Prueba de frenado | G36: Movil 1 AB743ZN | H36: Descelerometro | K36: Pista | M36: =IF(K36="",0,VLOOKUP(K36,#REF!,2,FALSE)) -> #REF! | N36: =IF(L36="",0,VLOOKUP(L36,#REF!,2,FALSE)) -> 0 | O36: =M36+N36 -> #REF! | P36: =IF(F36="Barrido","",O36) -> #REF! | Q36: =IF(F36="Barrido",O36,"") | R36: =IF(I36<>"0",I36,"") -> 0 | S36: =IF(J36<>"0",J36,"") -> 0 | T36: -5.2 | U36: -5.4 | V36: 99 | W36: 1004 | X36: 3.5
A37: 45824 | B37: =IF(A37="","",VLOOKUP(Planilla!A37,#REF!,2,FALSE)) -> #REF! | C37: =IF(B37="","",VLOOKUP(Planilla!A37,#REF!,3,FALSE)) -> #REF! | D37: Preventivo | E37: Rocio helado | F37: Rociado | G37: Tractor MF7615 2019 | H37: Rociador de Glicol Capurelli | J37: 1000 | K37: Pista, cabeceras, rodajes y plataforma | M37: =IF(K37="",0,VLOOKUP(K37,#REF!,2,FALSE)) -> #REF! | N37: =IF(L37="",0,VLOOKUP(L37,#REF!,2,FALSE)) -> 0 | O37: =M37+N37 -> #REF! | P37: =IF(F37="Barrido","",O37) -> #REF! | Q37: =IF(F37="Barrido",O37,"") | R37: =IF(I37<>"0",I37,"") -> 0 | S37: =IF(J37<>"0",J37,"") -> 1000 | T37: -6 | U37: -5 | V37: 99 | W37: 1002 | X37: 0
A38: 45824 | B38: =IF(A38="","",VLOOKUP(Planilla!A38,#REF!,2,FALSE)) -> #REF! | C38: =IF(B38="","",VLOOKUP(Planilla!A38,#REF!,3,FALSE)) -> #REF! | D38: Preventivo | E38: Probabilidad de Hielo | F38: Prueba de frenado | G38: Movil 1 AB743ZN | H38: Descelerometro | K38: Pista | M38: =IF(K38="",0,VLOOKUP(K38,#REF!,2,FALSE)) -> #REF! | N38: =IF(L38="",0,VLOOKUP(L38,#REF!,2,FALSE)) -> 0 | O38: =M38+N38 -> #REF! | P38: =IF(F38="Barrido","",O38) -> #REF! | Q38: =IF(F38="Barrido",O38,"") | R38: =IF(I38<>"0",I38,"") -> 0 | S38: =IF(J38<>"0",J38,"") -> 0 | T38: 1 | U38: 0 | V38: 98 | W38: 1024 | X38: 12
A39: 45824 | B39: =IF(A39="","",VLOOKUP(Planilla!A39,#REF!,2,FALSE)) -> #REF! | C39: =IF(B39="","",VLOOKUP(Planilla!A39,#REF!,3,FALSE)) -> #REF! | D39: Preventivo | E39: Probabilidad de Hielo | F39: Prueba de frenado | G39: Movil 1 AB743ZN | H39: Descelerometro | K39: Pista | M39: =IF(K39="",0,VLOOKUP(K39,#REF!,2,FALSE)) -> #REF! | N39: =IF(L39="",0,VLOOKUP(L39,#REF!,2,FALSE)) -> 0 | O39: =M39+N39 -> #REF! | P39: =IF(F39="Barrido","",O39) -> #REF! | Q39: =IF(F39="Barrido",O39,"") | R39: =IF(I39<>"0",I39,"") -> 0 | S39: =IF(J39<>"0",J39,"") -> 0 | T39: 0 | U39: 0 | V39: 97 | W39: 1024 | X39: 12
A40: 45825 | B40: =IF(A40="","",VLOOKUP(Planilla!A40,#REF!,2,FALSE)) -> #REF! | C40: =IF(B40="","",VLOOKUP(Planilla!A40,#REF!,3,FALSE)) -> #REF! | D40: Preventivo | E40: Probabilidad de Hielo | F40: Rociado | G40: Tractor MF7615 2019 | H40: Rociador de Glicol Capurelli | J40: 500 | K40: Parking, sendas peatonales | M40: =IF(K40="",0,VLOOKUP(K40,#REF!,2,FALSE)) -> #REF! | N40: =IF(L40="",0,VLOOKUP(L40,#REF!,2,FALSE)) -> 0 | O40: =M40+N40 -> #REF! | P40: =IF(F40="Barrido","",O40) -> #REF! | Q40: =IF(F40="Barrido",O40,"") | R40: =IF(I40<>"0",I40,"") -> 0 | S40: =IF(J40<>"0",J40,"") -> 500 | T40: -0.5 | U40: -1 | V40: 95 | W40: 1003 | X40: 18.7
...
